Workbook
Name Database_Character_Date: 'Characters Database'!$M$6:$M$350
Name Database_Character_Class: 'Characters Database'!$F$6:$F$350
Name Database_Character_Stars: 'Characters Database'!$L$6:$L$350
Name Database_Character_Image_Link: 'Characters Database'!$I$6:$I$350
Name Database_Character_Type_Image: 'Characters Database'!$C$6:$C$350
Name Database_Character_Tags: 'Characters Database'!$G$6:$G$350
Name Database_Character_Type: 'Characters Database'!$B$6:$B$350
Name Database_Character_Type_Image_Link: 'Characters Database'!$J$6:$J$350
Name Database_Character_Name: 'Characters Database'!$E$6:$E$350
Name Database_Character_Image: 'Characters Database'!$D$6:$D$350
Name Database_Character_ID: 'Characters Database'!$A$6:$A$350

Sheet Characters Database
A1: 🌟If you have any suggestions to improve the sheet, please insert a comment in this cell with your idea.
A2: 📥Download Link
A3: OPBR Traits Database v.26.01.27
A4: OPBR Medals Database v.26.01.27
A5: ☕Support my work & keep OPBR sheets updated. Thanks💖
C6: {=IFERROR(IF(J6:J350 <> "", IMAGE(J6:J350), "-"), )} -> - | D6: {=IF(I6:I350 <> "",IMAGE(I6:I350), "-")} -> - | J6: =IFERROR(__xludf.DUMMYFUNCTION("IFERROR(ARRAYFORMULA(IFS( REGEXMATCH(B6:B350, ""^Red\nAttacker$"" ), ""https://i.postimg.cc/L6B2DCYf/Red-Attacker.png"", REGEXMATCH(B6:B350, ""^Red\nDefender$"" ), ""https://i.postimg.cc/P5XhRWY7/Red-Defender.png"", REGEXMATCH(B6:B350, ""^Red\"&"nRunner$"" ), ""https://i.postimg.cc/Hk6HDrtk/Red-Runner.png"", REGEXMATCH(B6:B350, ""^Blue\nAttacker$"" ), ""https://i.postimg.cc/1zRtDxvf/Blue-Attacker.png"", REGEXMATCH(B6:B350, ""^Blue\nDefender$"" ), ""https://i.postimg.cc/m2xg81dx"&"/Blue-Defender.png"", REGEXMATCH(B6:B350, ""^Blue\nRunner$"" ), ""https://i.postimg.cc/4NzNM4MY/Blue-Runner.png"", REGEXMATCH(B6:B350, ""^Green\nAttacker$"" ), ""https://i.postimg.cc/0NH8mz6B/Green-Attacker.png"", REGEXMATCH(B6:B350, ""^Green\"&"nDefender$"" ), ""https://i.postimg.cc/qRhpGpyM/Green-Defender.png"", REGEXMATCH(B6:B350, ""^Green\nRunner$"" ), ""https://i.postimg.cc/PxgT30Qb/Green-Runner.png"", REGEXMATCH(B6:B350, ""^Light\nAttacker$"" ), ""https://i.postimg.cc/NGXg9fQ"&"d/Light-Attacker.png"", REGEXMATCH(B6:B350, ""^Light\nDefender$"" ), ""https://i.postimg.cc/0j7xLZVT/Light-Defender.png"", REGEXMATCH(B6:B350, ""^Light\nRunner$"" ), ""https://i.postimg.cc/02q9pRQP/Light-Runner.png"", REGEXMATCH(B6:B350, ""^Dar"&"k\nAttacker$"" ), ""https://i.postimg.cc/QdmN84js/Dark-Attacker.png"", REGEXMATCH(B6:B350, ""^Dark\nDefender$"" ), ""https://i.postimg.cc/qv4MdVVj/Dark-Defender.png"", REGEXMATCH(B6:B350, ""^Dark\nRunner$"" ), ""https://i.postimg.cc/rppVK"&"1p4/Dark-Runner.png"", REGEXMATCH(B6:B350, ""Red\nDefender-"" ), ""https://i.postimg.cc/k4wqRxyN/Transforming-Class-Red-Defender.png"", REGEXMATCH(B6:B350, ""Blue\nAttacker-"" ), ""https://i.postimg.cc/J0nmNGTf/Transforming-Class-Blue-Attacke"&"r.png"", REGEXMATCH(B6:B350, ""Blue\nRunner-"" ), ""https://i.postimg.cc/bN48nY15/Transforming-Class-Blue-Runner.png"", REGEXMATCH(B6:B350, ""Green\nDefender-"" ), ""https://i.postimg.cc/vZ9ytRzZ/Transforming-Class-Green-Defender.png"", REGEXMA"&"TCH(B6:B350, ""Light\nAttacker-"" ), ""https://i.postimg.cc/0j0ZVpyR/Transforming-Class-Light-Attacker.png"", REGEXMATCH(B6:B350, ""Dark\nDefender-"" ), ""https://i.postimg.cc/MZPzWmHq/Transforming-Class-Dark-Defender.png"", REGEXMATCH(B6:B350, "&"""Dark\nRunner-"" ), ""https://i.postimg.cc/Kv1x433L/Transforming-Class-Dark-Runner.png"", REGEXMATCH(B6:B350, ""^Red-.*\nAttacker"" ), ""https://i.postimg.cc/KjHbJxwR/Transforming-Element-Red-Attacker.png"", REGEXMATCH(B6:B350, ""^Blue-.*\nAtt"&"acker""), ""https://i.postimg.cc/P52mhmnd/Transforming-Element-Blue-Attacker.png"", REGEXMATCH(B6:B350, ""^Green-.*\nAttacker""), ""https://i.postimg.cc/bJqqv61N/Transforming-Element-Green-Attacker.png"", REGEXMATCH(B6:B350, ""^Dark-.*\nAttacker""), ""h"&"ttps://i.postimg.cc/nLHLrFW9/Transforming-Element-Dark-Attacker.png"" )), )"),"") | K6: {=IF(B6:B350 <> "" , B6:B350, )} | L6: =IFERROR(__xludf.DUMMYFUNCTION("ARRAYFORMULA(IFERROR( IFS( REGEXMATCH(F6:F350,""2 Stars""),""2 Stars"", REGEXMATCH(F6:F350,""3 Stars""),""3 Stars"", REGEXMATCH(F6:F350,""4 Stars|Step Up|Bounty Festival|Extreme|Cola""),""4 Stars"" ), ))"),"") | M6: =IFERROR(__xludf.DUMMYFUNCTION("ARRAYFORMULA(IF(A6:A350 <> """", LOOKUP(ROW(H6:H350), FILTER(ROW(H6:H350), H6:H350<>""""), FILTER(H6:H350, H6:H350<>"""")), ))"),"")
A7: =A8+1 -> 343 | B7: Dark Defender | E7: Baroque Works / Officer Agent Mr. 5 | F7: Step Up | G7: Defender(s) Baroque Works Paramecia Power users The Grand Line | H7: 46063 | I7: https://i.postimg.cc/MZLRHkwV/343-Baroque-Works-Officer-Agent-Mr-3.png | J7: =IFERROR(__xludf.DUMMYFUNCTION("""COMPUTED_VALUE"""),"https://i.postimg.cc/qv4MdVVj/Dark-Defender.png") -> https://i.postimg.cc/qv4MdVVj/Dark-Defender.png | K7: Dark Defender | L7: =IFERROR(__xludf.DUMMYFUNCTION("""COMPUTED_VALUE"""),"4 Stars") -> 4 Stars | M7: =IFERROR(__xludf.DUMMYFUNCTION("""COMPUTED_VALUE"""),46063.0) -> 46063
A8: =A9+1 -> 342 | B8: Green Runner | E8: Baroque Works / Officer Agent Ms. Valentine | F8: Step Up | G8: Runner(s) Baroque Works Paramecia Power users The Grand Line | I8: https://i.postimg.cc/KcWLjXbt/342-Baroque-Works-Officer-Agent-Ms-Valentine.png | J8: =IFERROR(__xludf.DUMMYFUNCTION("""COMPUTED_VALUE"""),"https://i.postimg.cc/PxgT30Qb/Green-Runner.png") -> https://i.postimg.cc/PxgT30Qb/Green-Runner.png | K8: Green Runner | L8: =IFERROR(__xludf.DUMMYFUNCTION("""COMPUTED_VALUE"""),"4 Stars") -> 4 Stars | M8: =IFERROR(__xludf.DUMMYFUNCTION("""COMPUTED_VALUE"""),46063.0) -> 46063
A9: =A10+1 -> 341 | B9: Dark-Light Attacker | E9: The Four Emperors Marshall D. Teach | F9: Extreme | G9: Attacker(s) The Seven Warlords of the Sea / Former Warlords of the Sea Paramecia Logia Captain Power users New World Worst Generation Blackbeard Pirates | H9: 46049 | I9: https://i.postimg.cc/2ST14Lhy/341-The-Four-Emperors-Marshall-D-Teach.png | J9: =IFERROR(__xludf.DUMMYFUNCTION("""COMPUTED_VALUE"""),"https://i.postimg.cc/nLHLrFW9/Transforming-Element-Dark-Attacker.png") -> https://i.postimg.cc/nLHLrFW9/Transforming-Element-Dark-Attacker.png | K9: Dark-Light Attacker | L9: =IFERROR(__xludf.DUMMYFUNCTION("""COMPUTED_VALUE"""),"4 Stars") -> 4 Stars | M9: =IFERROR(__xludf.DUMMYFUNCTION("""COMPUTED_VALUE"""),46049.0) -> 46049
A10: =A11+1 -> 340 | B10: Light Attacker-Defender-Runner | E10: ASL Ace & Sabo & Luffy | F10: Bounty Festival | G10: Attacker(s) East Blue Paramecia Power users | H10: 46023 | I10: https://i.postimg.cc/Jz7CBYLG/340-ASL-Ace-Sabo-Luffy.png | J10: =IFERROR(__xludf.DUMMYFUNCTION("""COMPUTED_VALUE"""),"https://i.postimg.cc/0j0ZVpyR/Transforming-Class-Light-Attacker.png") -> https://i.postimg.cc/0j0ZVpyR/Transforming-Class-Light-Attacker.png | K10: Light Attacker-Defender-Runner | L10: =IFERROR(__xludf.DUMMYFUNCTION("""COMPUTED_VALUE"""),"4 Stars") -> 4 Stars | M10: =IFERROR(__xludf.DUMMYFUNCTION("""COMPUTED_VALUE"""),46023.0) -> 46023
A11: =A12+1 -> 339 | B11: Red Runner | E11: Winner Island Trafalgar Law | F11: Extreme | G11: Runner(s) The Seven Warlords of the Sea / Former Warlords of the Sea Paramecia Captain Power users New World Worst Generation | H11: 46009 | I11: https://i.postimg.cc/DZzPtPj6/339-Winner-Island-Trafalgar-Law.png | J11: =IFERROR(__xludf.DUMMYFUNCTION("""COMPUTED_VALUE"""),"https://i.postimg.cc/Hk6HDrtk/Red-Runner.png") -> https://i.postimg.cc/Hk6HDrtk/Red-Runner.png | K11: Red Runner | L11: =IFERROR(__xludf.DUMMYFUNCTION("""COMPUTED_VALUE"""),"4 Stars") -> 4 Stars | M11: =IFERROR(__xludf.DUMMYFUNCTION("""COMPUTED_VALUE"""),46009.0) -> 46009
A12: =A13+1 -> 338 | B12: Light Defender | E12: Winner Island Bepo | F12: Bounty Festival | G12: Defender(s) New World Minks | H12: 46000 | I12: https://i.postimg.cc/tC85ZhVM/338-Winner-Island-Bepo.png | J12: =IFERROR(__xludf.DUMMYFUNCTION("""COMPUTED_VALUE"""),"https://i.postimg.cc/0j7xLZVT/Light-Defender.png") -> https://i.postimg.cc/0j7xLZVT/Light-Defender.png | K12: Light Defender | L12: =IFERROR(__xludf.DUMMYFUNCTION("""COMPUTED_VALUE"""),"4 Stars") -> 4 Stars | M12: =IFERROR(__xludf.DUMMYFUNCTION("""COMPUTED_VALUE"""),46000.0) -> 46000
A13: =A14+1 -> 337 | B13: Green Runner | E13: Genius Scientist Vegapunk | F13: Bounty Festival | G13: Runner(s) Navy Paramecia Power users New World Long-Range Normal Attacks | H13: 45986 | I13: https://i.postimg.cc/XvHRZRhz/337-Genius-Scientist-Vegapunk.png | J13: =IFERROR(__xludf.DUMMYFUNCTION("""COMPUTED_VALUE"""),"https://i.postimg.cc/PxgT30Qb/Green-Runner.png") -> https://i.postimg.cc/PxgT30Qb/Green-Runner.png | K13: Green Runner | L13: =IFERROR(__xludf.DUMMYFUNCTION("""COMPUTED_VALUE"""),"4 Stars") -> 4 Stars | M13: =IFERROR(__xludf.DUMMYFUNCTION("""COMPUTED_VALUE"""),45986.0) -> 45986
A14: =A15+1 -> 336 | B14: Red Attacker | E14: Father and Daughter Kuma & Bonney | F14: Bounty Festival | G14: Attacker(s) The Seven Warlords of the Sea / Former Warlords of the Sea Revolutionary Army Paramecia Captain Power users New World Worst Generation Royalty / Former Royalty | I14: https://i.postimg.cc/5t7hHhGr/336-Father-and-Daughter-Kuma-Bonney.png | J14: =IFERROR(__xludf.DUMMYFUNCTION("""COMPUTED_VALUE"""),"https://i.postimg.cc/L6B2DCYf/Red-Attacker.png") -> https://i.postimg.cc/L6B2DCYf/Red-Attacker.png | K14: Red Attacker | L14: =IFERROR(__xludf.DUMMYFUNCTION("""COMPUTED_VALUE"""),"4 Stars") -> 4 Stars | M14: =IFERROR(__xludf.DUMMYFUNCTION("""COMPUTED_VALUE"""),45986.0) -> 45986
A15: =A16+1 -> 335 | B15: Dark Runner | E15: Egghead Jinbe | F15: Bounty Festival | G15: Runner(s) The Seven Warlords of the Sea / Former Warlords of the Sea Straw Hat Pirates Fish-Man New World | H15: 45959 | I15: https://i.postimg.cc/sxMBVywR/335-Egghead-Jimbie.png | J15: =IFERROR(__xludf.DUMMYFUNCTION("""COMPUTED_VALUE"""),"https://i.postimg.cc/rppVK1p4/Dark-Runner.png") -> https://i.postimg.cc/rppVK1p4/Dark-Runner.png | K15: Dark Runner | L15: =IFERROR(__xludf.DUMMYFUNCTION("""COMPUTED_VALUE"""),"4 Stars") -> 4 Stars | M15: =IFERROR(__xludf.DUMMYFUNCTION("""COMPUTED_VALUE"""),45959.0) -> 45959
A16: =A17+1 -> 334 | B16: Dark Attacker | E16: Egghead Franky | F16: Bounty Festival | G16: Attacker(s) Straw Hat Pirates New World | I16: https://i.postimg.cc/Gt4Bcrqw/334-Egghead-Franky.png | J16: =IFERROR(__xludf.DUMMYFUNCTION("""COMPUTED_VALUE"""),"https://i.postimg.cc/QdmN84js/Dark-Attacker.png") -> https://i.postimg.cc/QdmN84js/Dark-Attacker.png | K16: Dark Attacker | L16: =IFERROR(__xludf.DUMMYFUNCTION("""COMPUTED_VALUE"""),"4 Stars") -> 4 Stars | M16: =IFERROR(__xludf.DUMMYFUNCTION("""COMPUTED_VALUE"""),45959.0) -> 45959
A17: =A18+1 -> 333 | B17: Dark Defender-Runner | E17: The Five Elders St. Jaygarcia Saturn | F17: Extreme | G17: Defender(s) New World Celestial Dragons / Former Celestial Dragons | H17: 45946 | I17: https://i.postimg.cc/28691fqR/333-The-Five-Elders-St-Jaygarcia-Saturn.png | J17: =IFERROR(__xludf.DUMMYFUNCTION("""COMPUTED_VALUE"""),"https://i.postimg.cc/MZPzWmHq/Transforming-Class-Dark-Defender.png") -> https://i.postimg.cc/MZPzWmHq/Transforming-Class-Dark-Defender.png | K17: Dark Defender-Runner | L17: =IFERROR(__xludf.DUMMYFUNCTION("""COMPUTED_VALUE"""),"4 Stars") -> 4 Stars | M17: =IFERROR(__xludf.DUMMYFUNCTION("""COMPUTED_VALUE"""),45946.0) -> 45946
A18: =A19+1 -> 332 | B18: Light Defender | E18: Egghead Nico Robin | F18: Bounty Festival | G18: Defender(s) Straw Hat Pirates Paramecia Power users New World | H18: 45929 | I18: https://i.postimg.cc/nLqZkVQz/332-Egghead-Nico-Robin.png | J18: =IFERROR(__xludf.DUMMYFUNCTION("""COMPUTED_VALUE"""),"https://i.postimg.cc/0j7xLZVT/Light-Defender.png") -> https://i.postimg.cc/0j7xLZVT/Light-Defender.png | K18: Light Defender | L18: =IFERROR(__xludf.DUMMYFUNCTION("""COMPUTED_VALUE"""),"4 Stars") -> 4 Stars | M18: =IFERROR(__xludf.DUMMYFUNCTION("""COMPUTED_VALUE"""),45929.0) -> 45929
A19: =A20+1 -> 331 | B19: Light Attacker-Defender | E19: Egghead Tony Tony Chopper | F19: Bounty Festival | G19: Attacker(s) Straw Hat Pirates Zoan Power users New World | I19: https://i.postimg.cc/fLZsg4xb/331-Egghead-Tony-Tony-Chopper.png | J19: =IFERROR(__xludf.DUMMYFUNCTION("""COMPUTED_VALUE"""),"https://i.postimg.cc/0j0ZVpyR/Transforming-Class-Light-Attacker.png") -> https://i.postimg.cc/0j0ZVpyR/Transforming-Class-Light-Attacker.png | K19: Light Attacker-Defender | L19: =IFERROR(__xludf.DUMMYFUNCTION("""COMPUTED_VALUE"""),"4 Stars") -> 4 Stars | M19: =IFERROR(__xludf.DUMMYFUNCTION("""COMPUTED_VALUE"""),45929.0) -> 45929
A20: =A21+1 -> 330 | B20: Blue-Red-Green Attacker | E20: Egghead Brook | F20: Bounty Festival | G20: Attacker(s) Straw Hat Pirates Paramecia Power users New World | H20: 45919 | I20: https://i.postimg.cc/L84ykwkF/330-Egghead-Brook.png | J20: =IFERROR(__xludf.DUMMYFUNCTION("""COMPUTED_VALUE"""),"https://i.postimg.cc/P52mhmnd/Transforming-Element-Blue-Attacker.png") -> https://i.postimg.cc/P52mhmnd/Transforming-Element-Blue-Attacker.png | K20: Blue-Red-Green Attacker | L20: =IFERROR(__xludf.DUMMYFUNCTION("""COMPUTED_VALUE"""),"4 Stars") -> 4 Stars | M20: =IFERROR(__xludf.DUMMYFUNCTION("""COMPUTED_VALUE"""),45919.0) -> 45919
A21: =A22+1 -> 329 | B21: Light Runner | E21: The Four Emperors Monkey D. Luffy | F21: Extreme | G21: Runner(s) Straw Hat Pirates Zoan Captain Power users New World Worst Generation | H21: 45897 | I21: https://i.postimg.cc/pVzdz7Qm/329-The-Four-Emperors-Monkey-D-Luffy.png | J21: =IFERROR(__xludf.DUMMYFUNCTION("""COMPUTED_VALUE"""),"https://i.postimg.cc/02q9pRQP/Light-Runner.png") -> https://i.postimg.cc/02q9pRQP/Light-Runner.png | K21: Light Runner | L21: =IFERROR(__xludf.DUMMYFUNCTION("""COMPUTED_VALUE"""),"4 Stars") -> 4 Stars | M21: =IFERROR(__xludf.DUMMYFUNCTION("""COMPUTED_VALUE"""),45897.0) -> 45897
A22: =A23+1 -> 328 | B22: Light Defender | E22: Egghead Usopp | F22: Bounty Festival | G22: Defender(s) Straw Hat Pirates New World Long-Range Normal Attacks | H22: 45876 | I22: https://i.postimg.cc/pV7FD1Sz/328-Egghead-Usopp.png | J22: =IFERROR(__xludf.DUMMYFUNCTION("""COMPUTED_VALUE"""),"https://i.postimg.cc/0j7xLZVT/Light-Defender.png") -> https://i.postimg.cc/0j7xLZVT/Light-Defender.png | K22: Light Defender | L22: =IFERROR(__xludf.DUMMYFUNCTION("""COMPUTED_VALUE"""),"4 Stars") -> 4 Stars | M22: =IFERROR(__xludf.DUMMYFUNCTION("""COMPUTED_VALUE"""),45876.0) -> 45876
A23: =A24+1 -> 327 | B23: Red Runner | E23: Egghead Nami | F23: Bounty Festival | G23: Runner(s) Straw Hat Pirates New World | I23: https://i.postimg.cc/50KFKP2c/327-Egghead-Nami.png | J23: =IFERROR(__xludf.DUMMYFUNCTION("""COMPUTED_VALUE"""),"https://i.postimg.cc/Hk6HDrtk/Red-Runner.png") -> https://i.postimg.cc/Hk6HDrtk/Red-Runner.png | K23: Red Runner | L23: =IFERROR(__xludf.DUMMYFUNCTION("""COMPUTED_VALUE"""),"4 Stars") -> 4 Stars | M23: =IFERROR(__xludf.DUMMYFUNCTION("""COMPUTED_VALUE"""),45876.0) -> 45876
A24: =A25+1 -> 326 | B24: Light Runner | E24: Blind Swordsman Fujitora [Issho] | F24: Bounty Festival | G24: Runner(s) Navy Paramecia Power users New World Navy Admiral / Former Navy Admiral | H24: 45834 | I24: https://i.postimg.cc/Kz0LqhWx/326-Blind-Swordsman-Fujitora-Issho.png | J24: =IFERROR(__xludf.DUMMYFUNCTION("""COMPUTED_VALUE"""),"https://i.postimg.cc/02q9pRQP/Light-Runner.png") -> https://i.postimg.cc/02q9pRQP/Light-Runner.png | K24: Light Runner | L24: =IFERROR(__xludf.DUMMYFUNCTION("""COMPUTED_VALUE"""),"4 Stars") -> 4 Stars | M24: =IFERROR(__xludf.DUMMYFUNCTION("""COMPUTED_VALUE"""),45834.0) -> 45834
A25: =A26+1 -> 325 | B25: Red Defender | E25: Groves of Wrath Ryokugyu [Aramaki] | F25: Bounty Festival | G25: Defender(s) Navy Logia Power users New World Navy Admiral / Former Navy Admiral | I25: https://i.postimg.cc/0jrShHgm/325-Groves-of-Wrath-Ryokugyu-Aramaki.png | J25: =IFERROR(__xludf.DUMMYFUNCTION("""COMPUTED_VALUE"""),"https://i.postimg.cc/P5XhRWY7/Red-Defender.png") -> https://i.postimg.cc/P5XhRWY7/Red-Defender.png | K25: Red Defender | L25: =IFERROR(__xludf.DUMMYFUNCTION("""COMPUTED_VALUE"""),"4 Stars") -> 4 Stars | M25: =IFERROR(__xludf.DUMMYFUNCTION("""COMPUTED_VALUE"""),45834.0) -> 45834
A26: =A27+1 -> 324 | B26: Red-Blue-Green Attacker | E26: Ama no Murakumo Sword Kizaru [Borsalino] | F26: Extreme | G26: Attacker(s) Navy Logia Power users New World Navy Admiral / Former Navy Admiral | H26: 45825 | I26: https://i.postimg.cc/HLKWkgdw/324-Ama-no-Murakumo-Sword-Kizaru-Borsalino.png | J26: =IFERROR(__xludf.DUMMYFUNCTION("""COMPUTED_VALUE"""),"https://i.postimg.cc/KjHbJxwR/Transforming-Element-Red-Attacker.png") -> https://i.postimg.cc/KjHbJxwR/Transforming-Element-Red-Attacker.png | K26: Red-Blue-Green Attacker | L26: =IFERROR(__xludf.DUMMYFUNCTION("""COMPUTED_VALUE"""),"4 Stars") -> 4 Stars | M26: =IFERROR(__xludf.DUMMYFUNCTION("""COMPUTED_VALUE"""),45825.0) -> 45825
A27: =A28+1 -> 323 | B27: Red Runner | E27: Davy Back Fight Sanji | F27: Bounty Festival | G27: Runner(S Straw Hat Pirates The Grand Line | H27: 45797 | I27: https://i.postimg.cc/023G8RPz/323-Davy-Back-Fight-Sanji.png | J27: =IFERROR(__xludf.DUMMYFUNCTION("""COMPUTED_VALUE"""),"https://i.postimg.cc/Hk6HDrtk/Red-Runner.png") -> https://i.postimg.cc/Hk6HDrtk/Red-Runner.png | K27: Red Runner | L27: =IFERROR(__xludf.DUMMYFUNCTION("""COMPUTED_VALUE"""),"4 Stars") -> 4 Stars | M27: =IFERROR(__xludf.DUMMYFUNCTION("""COMPUTED_VALUE"""),45797.0) -> 45797
A28: =A29+1 -> 322 | B28: Green Defender | E28: Foxy Pirates / Captain Foxy | F28: Bounty Festival | G28: Defender(s) Paramecia Captain Power users The Grand Line | H28: 45782 | I28: https://i.postimg.cc/KzBkWfHQ/322-Davy-Back-Fight-Foxy.png | J28: =IFERROR(__xludf.DUMMYFUNCTION("""COMPUTED_VALUE"""),"https://i.postimg.cc/qRhpGpyM/Green-Defender.png") -> https://i.postimg.cc/qRhpGpyM/Green-Defender.png | K28: Green Defender | L28: =IFERROR(__xludf.DUMMYFUNCTION("""COMPUTED_VALUE"""),"4 Stars") -> 4 Stars | M28: =IFERROR(__xludf.DUMMYFUNCTION("""COMPUTED_VALUE"""),45782.0) -> 45782
A29: =A30+1 -> 321 | B29: Red Attacker | E29: Davy Back Fight Monkey D. Luffy | F29: Bounty Festival | G29: Attacker(s) Straw Hat Pirates Paramecia Captain Power users The Grand Line | I29: https://i.postimg.cc/tJbZGP0b/321-Davy-Back-Fight-Monkey-D-Luffy.png | J29: =IFERROR(__xludf.DUMMYFUNCTION("""COMPUTED_VALUE"""),"https://i.postimg.cc/L6B2DCYf/Red-Attacker.png") -> https://i.postimg.cc/L6B2DCYf/Red-Attacker.png | K29: Red Attacker | L29: =IFERROR(__xludf.DUMMYFUNCTION("""COMPUTED_VALUE"""),"4 Stars") -> 4 Stars | M29: =IFERROR(__xludf.DUMMYFUNCTION("""COMPUTED_VALUE"""),45782.0) -> 45782
A30: =A31+1 -> 320 | B30: Light Attacker | E30: Happosui Army / 13th Chief Sai | F30: Bounty Festival | G30: Attacker(s) New World Straw Hat Fleet | H30: 45771 | I30: https://i.postimg.cc/L6zzngtT/320-Happosui-Army-13th-Chief-Sai.png | J30: =IFERROR(__xludf.DUMMYFUNCTION("""COMPUTED_VALUE"""),"https://i.postimg.cc/NGXg9fQd/Light-Attacker.png") -> https://i.postimg.cc/NGXg9fQd/Light-Attacker.png | K30: Light Attacker | L30: =IFERROR(__xludf.DUMMYFUNCTION("""COMPUTED_VALUE"""),"4 Stars") -> 4 Stars | M30: =IFERROR(__xludf.DUMMYFUNCTION("""COMPUTED_VALUE"""),45771.0) -> 45771
A31: =A32+1 -> 319 | B31: Red Defender | E31: Tontatta Pirates / Captain Leo | F31: Bounty Festival | G31: Defender(s) Paramecia Captain Power users New World Straw Hat Fleet | I31: https://i.postimg.cc/hPFLD1dv/319-Tontatta-Pirates-Captain-Leo.png | J31: =IFERROR(__xludf.DUMMYFUNCTION("""COMPUTED_VALUE"""),"https://i.postimg.cc/P5XhRWY7/Red-Defender.png") -> https://i.postimg.cc/P5XhRWY7/Red-Defender.png | K31: Red Defender | L31: =IFERROR(__xludf.DUMMYFUNCTION("""COMPUTED_VALUE"""),"4 Stars") -> 4 Stars | M31: =IFERROR(__xludf.DUMMYFUNCTION("""COMPUTED_VALUE"""),45771.0) -> 45771
A32: =A33+1 -> 318 | B32: Light Defender | E32: Celestial Dragon St. Charlos | F32: 2 Stars | G32: Defender(s) The Grand Line Long-Range Normal Attacks Celestial Dragons / Former Celestial Dragons | H32: 45748 | I32: https://i.postimg.cc/j567pxV1/318-Celestial-Dragon-St-Charlos.png | J32: =IFERROR(__xludf.DUMMYFUNCTION("""COMPUTED_VALUE"""),"https://i.postimg.cc/0j7xLZVT/Light-Defender.png") -> https://i.postimg.cc/0j7xLZVT/Light-Defender.png | K32: Light Defender | L32: =IFERROR(__xludf.DUMMYFUNCTION("""COMPUTED_VALUE"""),"2 Stars") -> 2 Stars | M32: =IFERROR(__xludf.DUMMYFUNCTION("""COMPUTED_VALUE"""),45748.0) -> 45748
A33: =A34+1 -> 317 | B33: Green Attacker | E33: Clear-Clear Fruit Shiryu | F33: Bounty Festival | G33: Attacker(s) Paramecia Power users New World Blackbeard Pirates | H33: 45743 | I33: https://i.postimg.cc/c1gdF4rC/317-Clear-Clear-Fruit-Shiryu-Skill.png | J33: =IFERROR(__xludf.DUMMYFUNCTION("""COMPUTED_VALUE"""),"https://i.postimg.cc/0NH8mz6B/Green-Attacker.png") -> https://i.postimg.cc/0NH8mz6B/Green-Attacker.png | K33: Green Attacker | L33: =IFERROR(__xludf.DUMMYFUNCTION("""COMPUTED_VALUE"""),"4 Stars") -> 4 Stars | M33: =IFERROR(__xludf.DUMMYFUNCTION("""COMPUTED_VALUE"""),45743.0) -> 45743
A34: =A35+1 -> 316 | B34: Red Defender | E34: Strong-Strong Fruit Jesus Burgess | F34: Bounty Festival | G34: Defender(s) Paramecia Power users New World Blackbeard Pirates | I34: https://i.postimg.cc/s1d6cJ1Y/316-Strong-Strong-Fruit-Jesus-Burgess-Skill.png | J34: =IFERROR(__xludf.DUMMYFUNCTION("""COMPUTED_VALUE"""),"https://i.postimg.cc/P5XhRWY7/Red-Defender.png") -> https://i.postimg.cc/P5XhRWY7/Red-Defender.png | K34: Red Defender | L34: =IFERROR(__xludf.DUMMYFUNCTION("""COMPUTED_VALUE"""),"4 Stars") -> 4 Stars | M34: =IFERROR(__xludf.DUMMYFUNCTION("""COMPUTED_VALUE"""),45743.0) -> 45743
A35: =A36+1 -> 315 | B35: Green Defender | E35: Germa 66 Vinsmoke Yonji | F35: Bounty Festival | G35: Defender(s) New World Germa 66 Royalty / Former Royalty | H35: 45719 | I35: https://i.postimg.cc/d3Wx2hQ1/315-Germa-66-Vinsmoke-Yonji.png | J35: =IFERROR(__xludf.DUMMYFUNCTION("""COMPUTED_VALUE"""),"https://i.postimg.cc/qRhpGpyM/Green-Defender.png") -> https://i.postimg.cc/qRhpGpyM/Green-Defender.png | K35: Green Defender | L35: =IFERROR(__xludf.DUMMYFUNCTION("""COMPUTED_VALUE"""),"4 Stars") -> 4 Stars | M35: =IFERROR(__xludf.DUMMYFUNCTION("""COMPUTED_VALUE"""),45719.0) -> 45719
A36: =A37+1 -> 314 | B36: Blue Runner | E36: Germa 66 Vinsmoke Neji | F36: Bounty Festival | G36: Defender(s) New World Germa 66 Royalty / Former Royalty | I36: https://i.postimg.cc/ncz5HGTQ/314-Germa-66-Vinsmoke-Neji.png | J36: =IFERROR(__xludf.DUMMYFUNCTION("""COMPUTED_VALUE"""),"https://i.postimg.cc/4NzNM4MY/Blue-Runner.png") -> https://i.postimg.cc/4NzNM4MY/Blue-Runner.png | K36: Blue Runner | L36: =IFERROR(__xludf.DUMMYFUNCTION("""COMPUTED_VALUE"""),"4 Stars") -> 4 Stars | M36: =IFERROR(__xludf.DUMMYFUNCTION("""COMPUTED_VALUE"""),45719.0) -> 45719
A37: =A38+1 -> 313 | B37: Red Attacker | E37: Germa 66 Vinsmoke Ichiji | F37: Bounty Festival | G37: Attacker(s) New World Germa 66 Royalty / Former Royalty | I37: https://i.postimg.cc/PfK9sRbj/313-Germa-66-Vinsmoke-Ichiji.png | J37: =IFERROR(__xludf.DUMMYFUNCTION("""COMPUTED_VALUE"""),"https://i.postimg.cc/L6B2DCYf/Red-Attacker.png") -> https://i.postimg.cc/L6B2DCYf/Red-Attacker.png | K37: Red Attacker | L37: =IFERROR(__xludf.DUMMYFUNCTION("""COMPUTED_VALUE"""),"4 Stars") -> 4 Stars | M37: =IFERROR(__xludf.DUMMYFUNCTION("""COMPUTED_VALUE"""),45719.0) -> 45719
A38: =A39+1 -> 312 | B38: Green Runner | E38: Flame Emperor Sabo | F38: Extreme | G38: Runner(s) Revolutionary Army Logia Power users New World | H38: 45699 | I38: https://i.postimg.cc/13TGnV64/312-Flame-Emperor-Sabo.png | J38: =IFERROR(__xludf.DUMMYFUNCTION("""COMPUTED_VALUE"""),"https://i.postimg.cc/PxgT30Qb/Green-Runner.png") -> https://i.postimg.cc/PxgT30Qb/Green-Runner.png | K38: Green Runner | L38: =IFERROR(__xludf.DUMMYFUNCTION("""COMPUTED_VALUE"""),"4 Stars") -> 4 Stars | M38: =IFERROR(__xludf.DUMMYFUNCTION("""COMPUTED_VALUE"""),45699.0) -> 45699
A39: =A40+1 -> 311 | B39: Dark Defender-Attacker | E39: Assistant Fish-Man Karate Master Koala | F39: Step Up | G39: Defender(s) Revolutionary Army New World | H39: 45692 | I39: https://i.postimg.cc/Bv7cNzNX/311-Assistant-Fish-Man-Karate-Master-Koala.png | J39: =IFERROR(__xludf.DUMMYFUNCTION("""COMPUTED_VALUE"""),"https://i.postimg.cc/MZPzWmHq/Transforming-Class-Dark-Defender.png") -> https://i.postimg.cc/MZPzWmHq/Transforming-Class-Dark-Defender.png | K39: Dark Defender-Attacker | L39: =IFERROR(__xludf.DUMMYFUNCTION("""COMPUTED_VALUE"""),"4 Stars") -> 4 Stars | M39: =IFERROR(__xludf.DUMMYFUNCTION("""COMPUTED_VALUE"""),45692.0) -> 45692
A40: =A41+1 -> 310 | B40: Green Defender-Attacker | E40: Blackbeard Pirates Kuzan | F40: Extreme | G40: Defender(s) Logia Power users New World Blackbeard Pirates Navy Admiral / Former Navy Admiral | H40: 45685 | I40: https://i.postimg.cc/zB7mxZRD/310-Blackbeard-Pirates-Kuzan.png | J40: =IFERROR(__xludf.DUMMYFUNCTION("""COMPUTED_VALUE"""),"https://i.postimg.cc/vZ9ytRzZ/Transforming-Class-Green-Defender.png") -> https://i.postimg.cc/vZ9ytRzZ/Transforming-Class-Green-Defender.png | K40: Green Defender-Attacker | L40: =IFERROR(__xludf.DUMMYFUNCTION("""COMPUTED_VALUE"""),"4 Stars") -> 4 Stars | M40: =IFERROR(__xludf.DUMMYFUNCTION("""COMPUTED_VALUE"""),45685.0) -> 45685
...

Sheet Characters (ٍSorted) V.2
A2: 2 Stars | B2: =COUNTIF(4:4,"*") -> 20 | C2: {=IF(C4:EE4 <> "", IF(VLOOKUP(C4:EE4,'Characters Database'!$E$6:$I45, 5, False) = "", "-", IMAGE(VLOOKUP(C4:EE4,'Characters Database'!$E$6:$I45, 5, False))), )}
C3: {=IF(C4:EE4 <> "", IMAGE(VLOOKUP(C4:EE4,'Characters Database'!$E$6:$K45, 6, False)), )}
C4: =IFERROR(__xludf.DUMMYFUNCTION("TRANSPOSE(QUERY('Characters Database'!A$6:K45, ""Select E Where F = '"" & A2 & ""'""))"),"Celestial Dragon St. Charlos") -> Celestial Dragon St. Charlos | D4: =IFERROR(__xludf.DUMMYFUNCTION("""COMPUTED_VALUE"""),"Bounty Hunter Johnny") -> Bounty Hunter Johnny | E4: =IFERROR(__xludf.DUMMYFUNCTION("""COMPUTED_VALUE"""),"Bounty Hunter Yosaku") -> Bounty Hunter Yosaku | F4: =IFERROR(__xludf.DUMMYFUNCTION("""COMPUTED_VALUE"""),"Black Cat Pirates / Guard Butchie") -> Black Cat Pirates / Guard Butchie | G4: =IFERROR(__xludf.DUMMYFUNCTION("""COMPUTED_VALUE"""),"Black Cat Pirates / Captain Django") -> Black Cat Pirates / Captain Django | H4: =IFERROR(__xludf.DUMMYFUNCTION("""COMPUTED_VALUE"""),"Buggy Pirates / Chief of Staff Cabaji") -> Buggy Pirates / Chief of Staff Cabaji | I4: =IFERROR(__xludf.DUMMYFUNCTION("""COMPUTED_VALUE"""),"Navy Captain Morgan") -> Navy Captain Morgan | J4: =IFERROR(__xludf.DUMMYFUNCTION("""COMPUTED_VALUE"""),"The Idiot Son Helmeppo") -> The Idiot Son Helmeppo | K4: =IFERROR(__xludf.DUMMYFUNCTION("""COMPUTED_VALUE"""),"Alvida Pirates / Captain Alvida") -> Alvida Pirates / Captain Alvida | L4: =IFERROR(__xludf.DUMMYFUNCTION("""COMPUTED_VALUE"""),"Chore Boy Koby") -> Chore Boy Koby | M4: =IFERROR(__xludf.DUMMYFUNCTION("""COMPUTED_VALUE"""),"Mountain Bandits / Leader Higuma the Bear") -> Mountain Bandits / Leader Higuma the Bear | N4: =IFERROR(__xludf.DUMMYFUNCTION("""COMPUTED_VALUE"""),"Straw Hat Pirates / Musician Brook") -> Straw Hat Pirates / Musician Brook | O4: =IFERROR(__xludf.DUMMYFUNCTION("""COMPUTED_VALUE"""),"Straw Hat Pirates / Ship Carpenter Franky") -> Straw Hat Pirates / Ship Carpenter Franky | P4: =IFERROR(__xludf.DUMMYFUNCTION("""COMPUTED_VALUE"""),"Straw Hat Pirates / Archaeologist Nico Robin") -> Straw Hat Pirates / Archaeologist Nico Robin | Q4: =IFERROR(__xludf.DUMMYFUNCTION("""COMPUTED_VALUE"""),"Straw Hat Pirates / Doctor Tony Tony Chopper") -> Straw Hat Pirates / Doctor Tony Tony Chopper | R4: =IFERROR(__xludf.DUMMYFUNCTION("""COMPUTED_VALUE"""),"Straw Hat Pirates / Cook Sanji") -> Straw Hat Pirates / Cook Sanji | S4: =IFERROR(__xludf.DUMMYFUNCTION("""COMPUTED_VALUE"""),"Straw Hat Pirates / Sharp Shooter Usopp") -> Straw Hat Pirates / Sharp Shooter Usopp | T4: =IFERROR(__xludf.DUMMYFUNCTION("""COMPUTED_VALUE"""),"Straw Hat Pirates / Navigator Nami") -> Straw Hat Pirates / Navigator Nami | U4: =IFERROR(__xludf.DUMMYFUNCTION("""COMPUTED_VALUE"""),"Straw Hat Pirates / Combatant Roronoa Zoro") -> Straw Hat Pirates / Combatant Roronoa Zoro | V4: =IFERROR(__xludf.DUMMYFUNCTION("""COMPUTED_VALUE"""),"Straw Hat Pirates / Captain Monkey D. Luffy") -> Straw Hat Pirates / Captain Monkey D. Luffy
C5: {=IF(C4:EE4 <> "", VLOOKUP(C4:EE4,'Characters Database'!$E$6:$K45, 7, False), )} -> Light Defender | D5: Blue Runner | E5: Red Runner | F5: Blue Defender | G5: Red Defender | H5: Green Runner | I5: Blue Defender | J5: Green Runner | K5: Green Defender | L5: Red Defender | M5: Red Attacker | N5: Green Runner | O5: Red Defender | P5: Green Attacker | Q5: Red Runner | R5: Blue Attacker | S5: Blue Runner | T5: Green Runner | U5: Green Defender | V5: Red Attacker
A6: 3 Stars | B6: =COUNTIF(8:8,"*") -> 14 | C6: {=IF(C8:EE8 <> "", IF(VLOOKUP(C8:EE8,'Characters Database'!$E$6:$I45, 5, False) = "", "-", IMAGE(VLOOKUP(C8:EE8,'Characters Database'!$E$6:$I45, 5, False))), )}
C7: {=IF(C8:EE8 <> "", IMAGE(VLOOKUP(C8:EE8,'Characters Database'!$E$6:$K45, 6, False)), )}
C8: =IFERROR(__xludf.DUMMYFUNCTION("TRANSPOSE(QUERY('Characters Database'!A$6:K45, ""Select E Where F = '"" & A6 & ""'""))"),"Veau Vengeance Sanji") -> Veau Vengeance Sanji | D8: =IFERROR(__xludf.DUMMYFUNCTION("""COMPUTED_VALUE"""),"5t Hammer Usopp") -> 5t Hammer Usopp | E8: =IFERROR(__xludf.DUMMYFUNCTION("""COMPUTED_VALUE"""),"Climate Baton Nami") -> Climate Baton Nami | F8: =IFERROR(__xludf.DUMMYFUNCTION("""COMPUTED_VALUE"""),"Baroque Works / Frontier Agents Ms. Wednesday") -> Baroque Works / Frontier Agents Ms. Wednesday | G8: =IFERROR(__xludf.DUMMYFUNCTION("""COMPUTED_VALUE"""),"Slip-Slip Fruit Alvida") -> Slip-Slip Fruit Alvida | H8: =IFERROR(__xludf.DUMMYFUNCTION("""COMPUTED_VALUE"""),"Navy HQ / Master Chief Petty Officer Tashigi") -> Navy HQ / Master Chief Petty Officer Tashigi | I8: =IFERROR(__xludf.DUMMYFUNCTION("""COMPUTED_VALUE"""),"Arlong Pirates / Officer Choo") -> Arlong Pirates / Officer Choo | J8: =IFERROR(__xludf.DUMMYFUNCTION("""COMPUTED_VALUE"""),"Arlong Pirates / Officer Kuroobi") -> Arlong Pirates / Officer Kuroobi | K8: =IFERROR(__xludf.DUMMYFUNCTION("""COMPUTED_VALUE"""),"Arlong Pirates / Officer Hatchan") -> Arlong Pirates / Officer Hatchan | L8: =IFERROR(__xludf.DUMMYFUNCTION("""COMPUTED_VALUE"""),"Krieg`s Pirate Armada / Admiral Don Krieg") -> Krieg`s Pirate Armada / Admiral Don Krieg | M8: =IFERROR(__xludf.DUMMYFUNCTION("""COMPUTED_VALUE"""),"Krieg`s Pirate Armada / Battle Commander Gin") -> Krieg`s Pirate Armada / Battle Commander Gin | N8: =IFERROR(__xludf.DUMMYFUNCTION("""COMPUTED_VALUE"""),"Baratie / Head Chef Zeff") -> Baratie / Head Chef Zeff | O8: =IFERROR(__xludf.DUMMYFUNCTION("""COMPUTED_VALUE"""),"Black Cat Pirates / Former Captain Captain Kuro") -> Black Cat Pirates / Former Captain Captain Kuro | P8: =IFERROR(__xludf.DUMMYFUNCTION("""COMPUTED_VALUE"""),"Buggy Pirates / Captain Buggy") -> Buggy Pirates / Captain Buggy
C9: {=IF(C8:EE8 <> "", VLOOKUP(C8:EE8,'Characters Database'!$E$6:$K45, 7, False), )} -> Blue Defender | D9: Blue Attacker | E9: Green Attacker | F9: Blue Runner | G9: Green Runner | H9: Blue Runner | I9: Green Attacker | J9: Blue Defender | K9: Red Attacker | L9: Green Defender | M9: Red Attacker | N9: Red Defender | O9: Green Attacker | P9: Red Runner
A10: Free 3 Stars | B10: =COUNTIF(12:12,"*") -> 17 | C10: {=IF(C12:EE12 <> "", IF(VLOOKUP(C12:EE12,'Characters Database'!$E$6:$I45, 5, False) = "", "-", IMAGE(VLOOKUP(C12:EE12,'Characters Database'!$E$6:$I45, 5, False))), )}
C11: {=IF(C12:EE12 <> "", IMAGE(VLOOKUP(C12:EE12,'Characters Database'!$E$6:$K45, 7, False)), )}
C12: =IFERROR(__xludf.DUMMYFUNCTION("TRANSPOSE(QUERY('Characters Database'!A$6:K45, ""Select E Where F = '"" & A10 & ""'""))"),"Fake Straw Hat Pirates / Captain Demaro Black") -> Fake Straw Hat Pirates / Captain Demaro Black | D12: =IFERROR(__xludf.DUMMYFUNCTION("""COMPUTED_VALUE"""),"Disciple of the Martial Arts Kung Fu Jugon") -> Disciple of the Martial Arts Kung Fu Jugon | E12: =IFERROR(__xludf.DUMMYFUNCTION("""COMPUTED_VALUE"""),"Shandian Warrior Wyper") -> Shandian Warrior Wyper | F12: =IFERROR(__xludf.DUMMYFUNCTION("""COMPUTED_VALUE"""),"The Guardian of the Forest Gaimon") -> The Guardian of the Forest Gaimon | G12: =IFERROR(__xludf.DUMMYFUNCTION("""COMPUTED_VALUE"""),"Land of Wano Chopperemon") -> Land of Wano Chopperemon | H12: =IFERROR(__xludf.DUMMYFUNCTION("""COMPUTED_VALUE"""),"The Undefeated Woman Rebecca") -> The Undefeated Woman Rebecca | I12: =IFERROR(__xludf.DUMMYFUNCTION("""COMPUTED_VALUE"""),"Kid Pirates / Fighter Killer") -> Kid Pirates / Fighter Killer | J12: =IFERROR(__xludf.DUMMYFUNCTION("""COMPUTED_VALUE"""),"Grand Line Naval Base 5 / Captain Tashigi") -> Grand Line Naval Base 5 / Captain Tashigi | K12: =IFERROR(__xludf.DUMMYFUNCTION("""COMPUTED_VALUE"""),"Navy HQ / Vice Admiral Monkey D. Garb") -> Navy HQ / Vice Admiral Monkey D. Garb | L12: =IFERROR(__xludf.DUMMYFUNCTION("""COMPUTED_VALUE"""),"Happy Holiday Franky") -> Happy Holiday Franky | M12: =IFERROR(__xludf.DUMMYFUNCTION("""COMPUTED_VALUE"""),"Firetank Pirates / Godfather Capone Bege") -> Firetank Pirates / Godfather Capone Bege | N12: =IFERROR(__xludf.DUMMYFUNCTION("""COMPUTED_VALUE"""),"Legendary Samurai Zombie Ryuma") -> Legendary Samurai Zombie Ryuma | O12: =IFERROR(__xludf.DUMMYFUNCTION("""COMPUTED_VALUE"""),"Land of Wano Basil Hawkins") -> Land of Wano Basil Hawkins | P12: =IFERROR(__xludf.DUMMYFUNCTION("""COMPUTED_VALUE"""),"Bonney Pirates / Captain Jewelry Bonney") -> Bonney Pirates / Captain Jewelry Bonney | Q12: =IFERROR(__xludf.DUMMYFUNCTION("""COMPUTED_VALUE"""),"Alabasta / Princess Nefeltari Vivi") -> Alabasta / Princess Nefeltari Vivi | R12: =IFERROR(__xludf.DUMMYFUNCTION("""COMPUTED_VALUE"""),"Bellamy Pirates / Captain Bellamy") -> Bellamy Pirates / Captain Bellamy | S12: =IFERROR(__xludf.DUMMYFUNCTION("""COMPUTED_VALUE"""),"Obe-Sword Style Iai Lion Song Roronoa Zoro") -> Obe-Sword Style Iai Lion Song Roronoa Zoro
C13: {=IF(C12:EE12 <> "", VLOOKUP(C12:EE12,'Characters Database'!$E$6:$K45, 7, False), )} -> Light Defender | D13: Green-Red-Blue Attacker | E13: Red Runner | F13: Blue Defender | G13: Red Runner | H13: Green Defender | I13: Blue Runner | J13: Red Runner | K13: Green Defender | L13: Red Attacker | M13: Red Defender | N13: Green Attacker | O13: Blue Defender | P13: Green Runner | Q13: Red Runner | R13: Blue Defender | S13: Green Attacker
A14: Limited 3 Stars | B14: =COUNTIF(16:16,"*") -> 2 | C14: {=IF(C16:EE16 <> "", IF(VLOOKUP(C16:EE16,'Characters Database'!$E$6:$I45, 5, False) = "", "-", IMAGE(VLOOKUP(C16:EE16,'Characters Database'!$E$6:$I45, 5, False))), )}
C15: {=IF(C16:EE16 <> "", IMAGE(VLOOKUP(C16:EE16,'Characters Database'!$E$6:$K45, 6, False)), )}
C16: =IFERROR(__xludf.DUMMYFUNCTION("TRANSPOSE(QUERY('Characters Database'!A$6:K45, ""Select E Where F = '"" & A14 & ""'""))"),"FILM RED Monkey D. Luffy") -> FILM RED Monkey D. Luffy | D16: =IFERROR(__xludf.DUMMYFUNCTION("""COMPUTED_VALUE"""),"STAMPEDE Monkey D. Luffy") -> STAMPEDE Monkey D. Luffy
C17: {=IF(C16:EE16 <> "", VLOOKUP(C16:EE16,'Characters Database'!$E$6:$K45, 7, False), )} -> Red Attacker | D17: Blue Attacker
A18: Free 4 Stars | B18: =COUNTIF(20:20,"*") -> 3 | C18: {=IF(C20:EE20 <> "", IF(VLOOKUP(C20:EE20,'Characters Database'!$E$6:$I45, 5, False) = "", "-", IMAGE(VLOOKUP(C20:EE20,'Characters Database'!$E$6:$I45, 5, False))), )}
C19: {=IF(C20:EE20 <> "", IMAGE(VLOOKUP(C20:EE20,'Characters Database'!$E$6:$K45, 6, False)), )}
C20: =IFERROR(__xludf.DUMMYFUNCTION("TRANSPOSE(QUERY('Characters Database'!A$6:K45, ""Select E Where F = '"" & A18 & ""'""))"),"ODYSSEY Adio Suerte") -> ODYSSEY Adio Suerte | D20: =IFERROR(__xludf.DUMMYFUNCTION("""COMPUTED_VALUE"""),"The Parmount War Monkey D. Luffy") -> The Parmount War Monkey D. Luffy | E20: =IFERROR(__xludf.DUMMYFUNCTION("""COMPUTED_VALUE"""),"Red-Haired Pirates / Captain Shanks") -> Red-Haired Pirates / Captain Shanks
C21: {=IF(C20:EE20 <> "", VLOOKUP(C20:EE20,'Characters Database'!$E$6:$K45, 7, False), )} -> Blue Attacker | D21: Green Runner | E21: Red Defender
A22: Step Up | B22: =COUNTIF(24:24,"*") -> 105 | C22: {=IF(C24:EE24 <> "", IF(VLOOKUP(C24:EE24,'Characters Database'!$E$6:$I45, 5, False) = "", "-", IMAGE(VLOOKUP(C24:EE24,'Characters Database'!$E$6:$I45, 5, False))), )}
C23: {=IF(C24:EE24 <> "", IMAGE(VLOOKUP(C24:EE24,'Characters Database'!$E$6:$K45, 6, False)), )}
C24: =IFERROR(__xludf.DUMMYFUNCTION("TRANSPOSE(QUERY('Characters Database'!A$6:K45, ""Select E Where F = '"" & A22 & ""'""))"),"Baroque Works / Officer Agent Mr. 5") -> Baroque Works / Officer Agent Mr. 5 | D24: =IFERROR(__xludf.DUMMYFUNCTION("""COMPUTED_VALUE"""),"Baroque Works / Officer Agent Ms. Valentine") -> Baroque Works / Officer Agent Ms. Valentine | E24: =IFERROR(__xludf.DUMMYFUNCTION("""COMPUTED_VALUE"""),"Assistant Fish-Man Karate Master Koala") -> Assistant Fish-Man Karate Master Koala | F24: =IFERROR(__xludf.DUMMYFUNCTION("""COMPUTED_VALUE"""),"Navy HQ / Lt. Commander Helmeppo") -> Navy HQ / Lt. Commander Helmeppo | G24: =IFERROR(__xludf.DUMMYFUNCTION("""COMPUTED_VALUE"""),"Egghead Jewelry Bonney") -> Egghead Jewelry Bonney | H24: =IFERROR(__xludf.DUMMYFUNCTION("""COMPUTED_VALUE"""),"Punk-06 York") -> Punk-06 York | I24: =IFERROR(__xludf.DUMMYFUNCTION("""COMPUTED_VALUE"""),"Punk-05 Atlas") -> Punk-05 Atlas | J24: =IFERROR(__xludf.DUMMYFUNCTION("""COMPUTED_VALUE"""),"The Sky Knight Ganfor") -> The Sky Knight Ganfor | K24: =IFERROR(__xludf.DUMMYFUNCTION("""COMPUTED_VALUE"""),"Whole Cake Island Carrot") -> Whole Cake Island Carrot | L24: =IFERROR(__xludf.DUMMYFUNCTION("""COMPUTED_VALUE"""),"Land of Wano Otama & Komachiyo") -> Land of Wano Otama & Komachiyo | M24: =IFERROR(__xludf.DUMMYFUNCTION("""COMPUTED_VALUE"""),"Animal Kingdom Pirates / Tobi Roppo Black Maria") -> Animal Kingdom Pirates / Tobi Roppo Black Maria | N24: =IFERROR(__xludf.DUMMYFUNCTION("""COMPUTED_VALUE"""),"Revolutionary Army / Officer Inazuma") -> Revolutionary Army / Officer Inazuma | O24: =IFERROR(__xludf.DUMMYFUNCTION("""COMPUTED_VALUE"""),"Revolutionary Army / Solider Hack") -> Revolutionary Army / Solider Hack | P24: =IFERROR(__xludf.DUMMYFUNCTION("""COMPUTED_VALUE"""),"Animal Kingdom Pirates / Tobi Roppo Sasaki") -> Animal Kingdom Pirates / Tobi Roppo Sasaki | Q24: =IFERROR(__xludf.DUMMYFUNCTION("""COMPUTED_VALUE"""),"Caribou Pirates / Captain Caribou") -> Caribou Pirates / Captain Caribou | R24: =IFERROR(__xludf.DUMMYFUNCTION("""COMPUTED_VALUE"""),"Flying Pirates / Captain Vander Decken IX") -> Flying Pirates / Captain Vander Decken IX | S24: =IFERROR(__xludf.DUMMYFUNCTION("""COMPUTED_VALUE"""),"Triple-X-Level Boxer Ideo") -> Triple-X-Level Boxer Ideo | T24: =IFERROR(__xludf.DUMMYFUNCTION("""COMPUTED_VALUE"""),"The Kingdom of Prodence / King Elizabello II") -> The Kingdom of Prodence / King Elizabello II | U24: =IFERROR(__xludf.DUMMYFUNCTION("""COMPUTED_VALUE"""),"Big Mom Pirates / Crewmate Charoltte Oven") -> Big Mom Pirates / Crewmate Charoltte Oven | V24: =IFERROR(__xludf.DUMMYFUNCTION("""COMPUTED_VALUE"""),"Leader of the Whale Forest Guardians Pedro") -> Leader of the Whale Forest Guardians Pedro | W24: =IFERROR(__xludf.DUMMYFUNCTION("""COMPUTED_VALUE"""),"First Act as a Married Couple Charlotte Pudding") -> First Act as a Married Couple Charlotte Pudding | X24: =IFERROR(__xludf.DUMMYFUNCTION("""COMPUTED_VALUE"""),"Top Secret Special Force Captain of ""Sword"" X. Drake") -> Top Secret Special Force Captain of "Sword" X. Drake | Y24: =IFERROR(__xludf.DUMMYFUNCTION("""COMPUTED_VALUE"""),"Hyogoro Family / Big Boss Hyogoro") -> Hyogoro Family / Big Boss Hyogoro | Z24: =IFERROR(__xludf.DUMMYFUNCTION("""COMPUTED_VALUE"""),"Kozuki Clan / Servant Raizo") -> Kozuki Clan / Servant Raizo | AA24: =IFERROR(__xludf.DUMMYFUNCTION("""COMPUTED_VALUE"""),"Veteran Kunoichi Shinobu") -> Veteran Kunoichi Shinobu | AB24: =IFERROR(__xludf.DUMMYFUNCTION("""COMPUTED_VALUE"""),"The Bullet of Dressrosa Bellamy") -> The Bullet of Dressrosa Bellamy | AC24: =IFERROR(__xludf.DUMMYFUNCTION("""COMPUTED_VALUE"""),"Land of Wano Franosuke") -> Land of Wano Franosuke | AD24: =IFERROR(__xludf.DUMMYFUNCTION("""COMPUTED_VALUE"""),"Land of Wano Usohachi") -> Land of Wano Usohachi | AE24: =IFERROR(__xludf.DUMMYFUNCTION("""COMPUTED_VALUE"""),"Whitebeard Pirates / 5th Division Commander Vista") -> Whitebeard Pirates / 5th Division Commander Vista | AF24: =IFERROR(__xludf.DUMMYFUNCTION("""COMPUTED_VALUE"""),"Blackbeard Pirates / Helsman ""Champ"" Jesus Burgess") -> Blackbeard Pirates / Helsman "Champ" Jesus Burgess | AG24: =IFERROR(__xludf.DUMMYFUNCTION("""COMPUTED_VALUE"""),"Former Whitebeard Pirates / 16th Division Commander Izo") -> Former Whitebeard Pirates / 16th Division Commander Izo | AH24: =IFERROR(__xludf.DUMMYFUNCTION("""COMPUTED_VALUE"""),"Kurozumi Spy Kurozumi Kanjuro") -> Kurozumi Spy Kurozumi Kanjuro | AI24: =IFERROR(__xludf.DUMMYFUNCTION("""COMPUTED_VALUE"""),"Whole Cake Island Jinbe") -> Whole Cake Island Jinbe | AJ24: =IFERROR(__xludf.DUMMYFUNCTION("""COMPUTED_VALUE"""),"Big Mom Pirates / Crewmate Charlotte Pudding") -> Big Mom Pirates / Crewmate Charlotte Pudding | AK24: =IFERROR(__xludf.DUMMYFUNCTION("""COMPUTED_VALUE"""),"Don Quixote Pirates / Officer Monet") -> Don Quixote Pirates / Officer Monet | AL24: =IFERROR(__xludf.DUMMYFUNCTION("""COMPUTED_VALUE"""),"Don Quixote Pirates / Supreme Officer Vergo") -> Don Quixote Pirates / Supreme Officer Vergo | AM24: =IFERROR(__xludf.DUMMYFUNCTION("""COMPUTED_VALUE"""),"Don Quixote Pirates / Officer Señor Pink") -> Don Quixote Pirates / Officer Señor Pink | AN24: =IFERROR(__xludf.DUMMYFUNCTION("""COMPUTED_VALUE"""),"Don Quixote Pirates / Servant Assassin Baby 5") -> Don Quixote Pirates / Servant Assassin Baby 5 | AO24: =IFERROR(__xludf.DUMMYFUNCTION("""COMPUTED_VALUE"""),"Navy HQ / Science Team Captain Sentomaru") -> Navy HQ / Science Team Captain Sentomaru | AP24: =IFERROR(__xludf.DUMMYFUNCTION("""COMPUTED_VALUE"""),"Navy HQ / Master Chief Petty Officer Koby") -> Navy HQ / Master Chief Petty Officer Koby | AQ24: =IFERROR(__xludf.DUMMYFUNCTION("""COMPUTED_VALUE"""),"Land of Wano Bonekichi") -> Land of Wano Bonekichi | AR24: =IFERROR(__xludf.DUMMYFUNCTION("""COMPUTED_VALUE"""),"Land of Wano Orobi") -> Land of Wano Orobi | AS24: =IFERROR(__xludf.DUMMYFUNCTION("""COMPUTED_VALUE"""),"Baroque Works / Officer Agent Ms. Goldenweek") -> Baroque Works / Officer Agent Ms. Goldenweek | AT24: =IFERROR(__xludf.DUMMYFUNCTION("""COMPUTED_VALUE"""),"Baroque Works / Officer Agent Mr. 3") -> Baroque Works / Officer Agent Mr. 3 | AU24: =IFERROR(__xludf.DUMMYFUNCTION("""COMPUTED_VALUE"""),"King of the Night Cat Viper") -> King of the Night Cat Viper | AV24: =IFERROR(__xludf.DUMMYFUNCTION("""COMPUTED_VALUE"""),"King of the Day Dogstorm") -> King of the Day Dogstorm | AW24: =IFERROR(__xludf.DUMMYFUNCTION("""COMPUTED_VALUE"""),"Revolutionary Army / Officer Koala") -> Revolutionary Army / Officer Koala | AX24: =IFERROR(__xludf.DUMMYFUNCTION("""COMPUTED_VALUE"""),"Minks Carrot") -> Minks Carrot | AY24: =IFERROR(__xludf.DUMMYFUNCTION("""COMPUTED_VALUE"""),"Kozuki Clan / Servant Ashura Doji") -> Kozuki Clan / Servant Ashura Doji | AZ24: =IFERROR(__xludf.DUMMYFUNCTION("""COMPUTED_VALUE"""),"Kyoshiro Family / Boss Napping Kyoshiro") -> Kyoshiro Family / Boss Napping Kyoshiro | BA24: =IFERROR(__xludf.DUMMYFUNCTION("""COMPUTED_VALUE"""),"Kozuki Clan / Servant Kawamatsu") -> Kozuki Clan / Servant Kawamatsu | BB24: =IFERROR(__xludf.DUMMYFUNCTION("""COMPUTED_VALUE"""),"Most Handsome Swordman in the Land of Wano Kikunojo") -> Most Handsome Swordman in the Land of Wano Kikunojo | BC24: =IFERROR(__xludf.DUMMYFUNCTION("""COMPUTED_VALUE"""),"Fire Fist Portgaz D. Ace") -> Fire Fist Portgaz D. Ace | BD24: =IFERROR(__xludf.DUMMYFUNCTION("""COMPUTED_VALUE"""),"Former Navy Admiral Kuzan") -> Former Navy Admiral Kuzan | BE24: =IFERROR(__xludf.DUMMYFUNCTION("""COMPUTED_VALUE"""),"Punk Hazard Smoker (Chambres)") -> Punk Hazard Smoker (Chambres) | BF24: =IFERROR(__xludf.DUMMYFUNCTION("""COMPUTED_VALUE"""),"Ghost Princess Perona") -> Ghost Princess Perona | BG24: =IFERROR(__xludf.DUMMYFUNCTION("""COMPUTED_VALUE"""),"Former World Government / Science Division Member Caesar Clown") -> Former World Government / Science Division Member Caesar Clown | BH24: =IFERROR(__xludf.DUMMYFUNCTION("""COMPUTED_VALUE"""),"The Seven Warlords of the Sea Buggy") -> The Seven Warlords of the Sea Buggy | BI24: =IFERROR(__xludf.DUMMYFUNCTION("""COMPUTED_VALUE"""),"Don Quixote Family / Officer Corazon") -> Don Quixote Family / Officer Corazon | BJ24: =IFERROR(__xludf.DUMMYFUNCTION("""COMPUTED_VALUE"""),"Surgeon of Death Trafalger Law") -> Surgeon of Death Trafalger Law | BK24: =IFERROR(__xludf.DUMMYFUNCTION("""COMPUTED_VALUE"""),"Land of Wano Luffytaro") -> Land of Wano Luffytaro | BL24: =IFERROR(__xludf.DUMMYFUNCTION("""COMPUTED_VALUE"""),"Land of Wano Onami") -> Land of Wano Onami | BM24: =IFERROR(__xludf.DUMMYFUNCTION("""COMPUTED_VALUE"""),"On-Air Pirates / Captain Scratchmen Apoo") -> On-Air Pirates / Captain Scratchmen Apoo | BN24: =IFERROR(__xludf.DUMMYFUNCTION("""COMPUTED_VALUE"""),"Fallen Monk Pirates / Captain ""Mad Monk"" Urouge") -> Fallen Monk Pirates / Captain "Mad Monk" Urouge | BO24: =IFERROR(__xludf.DUMMYFUNCTION("""COMPUTED_VALUE"""),"Gear Four / Snakeman Monkey D. Luffy") -> Gear Four / Snakeman Monkey D. Luffy | BP24: =IFERROR(__xludf.DUMMYFUNCTION("""COMPUTED_VALUE"""),"Gerand Line Navel Base 5 / Vice Admiral Smoker") -> Gerand Line Navel Base 5 / Vice Admiral Smoker | BQ24: =IFERROR(__xludf.DUMMYFUNCTION("""COMPUTED_VALUE"""),"Navy HQ / Rear Admiral Hina") -> Navy HQ / Rear Admiral Hina | BR24: =IFERROR(__xludf.DUMMYFUNCTION("""COMPUTED_VALUE"""),"CP9 Kaku") -> CP9 Kaku | BS24: =IFERROR(__xludf.DUMMYFUNCTION("""COMPUTED_VALUE"""),"CP9 Rob Lucci") -> CP9 Rob Lucci | BT24: =IFERROR(__xludf.DUMMYFUNCTION("""COMPUTED_VALUE"""),"Beautiful Pirates / Captain Cavendish") -> Beautiful Pirates / Captain Cavendish | BU24: =IFERROR(__xludf.DUMMYFUNCTION("""COMPUTED_VALUE"""),"Barto Club / Captain Bartolomeo") -> Barto Club / Captain Bartolomeo | BV24: =IFERROR(__xludf.DUMMYFUNCTION("""COMPUTED_VALUE"""),"Whitebeard Pirates / 1st Division Commander Marco") -> Whitebeard Pirates / 1st Division Commander Marco | BW24: =IFERROR(__xludf.DUMMYFUNCTION("""COMPUTED_VALUE"""),"Son of the King of the Pirates Portgaz D. Ace") -> Son of the King of the Pirates Portgaz D. Ace | BX24: =IFERROR(__xludf.DUMMYFUNCTION("""COMPUTED_VALUE"""),"Happy Holiday Nico Robin") -> Happy Holiday Nico Robin | BY24: =IFERROR(__xludf.DUMMYFUNCTION("""COMPUTED_VALUE"""),"Happy Holiday Tony Tony Chopper") -> Happy Holiday Tony Tony Chopper | BZ24: =IFERROR(__xludf.DUMMYFUNCTION("""COMPUTED_VALUE"""),"Germa 66 Vinsmoke Reiju") -> Germa 66 Vinsmoke Reiju | CA24: =IFERROR(__xludf.DUMMYFUNCTION("""COMPUTED_VALUE"""),"Whole Cake Island Sanji") -> Whole Cake Island Sanji | CB24: =IFERROR(__xludf.DUMMYFUNCTION("""COMPUTED_VALUE"""),"Thriller Park Pirates / Mysterious Four Perona") -> Thriller Park Pirates / Mysterious Four Perona | CC24: =IFERROR(__xludf.DUMMYFUNCTION("""COMPUTED_VALUE"""),"Ray of Hope Nightmare Luffy") -> Ray of Hope Nightmare Luffy | CD24: =IFERROR(__xludf.DUMMYFUNCTION("""COMPUTED_VALUE"""),"Land of Wano Zorojuro") -> Land of Wano Zorojuro | CE24: =IFERROR(__xludf.DUMMYFUNCTION("""COMPUTED_VALUE"""),"Land of Wano Trafalgar Law") -> Land of Wano Trafalgar Law | CF24: =IFERROR(__xludf.DUMMYFUNCTION("""COMPUTED_VALUE"""),"2 Years Later / Ship Carpenter Franky") -> 2 Years Later / Ship Carpenter Franky | CG24: =IFERROR(__xludf.DUMMYFUNCTION("""COMPUTED_VALUE"""),"2 Years Later / Musician Brook") -> 2 Years Later / Musician Brook | CH24: =IFERROR(__xludf.DUMMYFUNCTION("""COMPUTED_VALUE"""),"2 Years Later / Archaeologist Nico Robin") -> 2 Years Later / Archaeologist Nico Robin | CI24: =IFERROR(__xludf.DUMMYFUNCTION("""COMPUTED_VALUE"""),"2 Years Later / Doctor Tony Tony Chopper") -> 2 Years Later / Doctor Tony Tony Chopper | CJ24: =IFERROR(__xludf.DUMMYFUNCTION("""COMPUTED_VALUE"""),"2 Years Later / Sharp Shooter Usopp") -> 2 Years Later / Sharp Shooter Usopp | CK24: =IFERROR(__xludf.DUMMYFUNCTION("""COMPUTED_VALUE"""),"2 Years Later / Cook Sanji") -> 2 Years Later / Cook Sanji | CL24: =IFERROR(__xludf.DUMMYFUNCTION("""COMPUTED_VALUE"""),"2 Years Later / Navigator Nami") -> 2 Years Later / Navigator Nami | CM24: =IFERROR(__xludf.DUMMYFUNCTION("""COMPUTED_VALUE"""),"2 Years Later / Combatant Roronoa Zoro") -> 2 Years Later / Combatant Roronoa Zoro | CN24: =IFERROR(__xludf.DUMMYFUNCTION("""COMPUTED_VALUE"""),"2 Years Later / Captain Monkey D. Luffy") -> 2 Years Later / Captain Monkey D. Luffy | CO24: =IFERROR(__xludf.DUMMYFUNCTION("""COMPUTED_VALUE"""),"Arm Point Tony Tony Chopper") -> Arm Point Tony Tony Chopper | CP24: =IFERROR(__xludf.DUMMYFUNCTION("""COMPUTED_VALUE"""),"108 Pound Phoenix Roronoa Zoro") -> 108 Pound Phoenix Roronoa Zoro | CQ24: =IFERROR(__xludf.DUMMYFUNCTION("""COMPUTED_VALUE"""),"Baroque Works / Vice President Ms. All Sunday") -> Baroque Works / Vice President Ms. All Sunday | CR24: =IFERROR(__xludf.DUMMYFUNCTION("""COMPUTED_VALUE"""),"Baroque Works / Officer Agent Bon Clay, aka Mr. 2") -> Baroque Works / Officer Agent Bon Clay, aka Mr. 2 | CS24: =IFERROR(__xludf.DUMMYFUNCTION("""COMPUTED_VALUE"""),"Kami Eneru") -> Kami Eneru | CT24: =IFERROR(__xludf.DUMMYFUNCTION("""COMPUTED_VALUE"""),"The Seven Warlords of the Sea Crocodile") -> The Seven Warlords of the Sea Crocodile | CU24: =IFERROR(__xludf.DUMMYFUNCTION("""COMPUTED_VALUE"""),"Peacock Slasher Nefeltari Vivi") -> Peacock Slasher Nefeltari Vivi | CV24: =IFERROR(__xludf.DUMMYFUNCTION("""COMPUTED_VALUE"""),"Gum-Gum Storm Monkey D. Luffy") -> Gum-Gum Storm Monkey D. Luffy | CW24: =IFERROR(__xludf.DUMMYFUNCTION("""COMPUTED_VALUE"""),"Drum Kingdom / Former Ruler Wapol") -> Drum Kingdom / Former Ruler Wapol | CX24: =IFERROR(__xludf.DUMMYFUNCTION("""COMPUTED_VALUE"""),"Navy HQ / Captain Smoker") -> Navy HQ / Captain Smoker | CY24: =IFERROR(__xludf.DUMMYFUNCTION("""COMPUTED_VALUE"""),"30 Million Berry Bounty Monkey D. Luffy") -> 30 Million Berry Bounty Monkey D. Luffy | CZ24: =IFERROR(__xludf.DUMMYFUNCTION("""COMPUTED_VALUE"""),"Arlong Pirates / Captain Arlong") -> Arlong Pirates / Captain Arlong | DA24: =IFERROR(__xludf.DUMMYFUNCTION("""COMPUTED_VALUE"""),"The Seven Warlords of the Sea Dracule Mihawk") -> The Seven Warlords of the Sea Dracule Mihawk | DB24: =IFERROR(__xludf.DUMMYFUNCTION("""COMPUTED_VALUE"""),"Girl from Syrub Village Kaya") -> Girl from Syrub Village Kaya | DC24: =IFERROR(__xludf.DUMMYFUNCTION("""COMPUTED_VALUE"""),"Red-Haired Pirates / Sharp Shooter Yasopp") -> Red-Haired Pirates / Sharp Shooter Yasopp
C25: {=IF(C24:EE24 <> "", VLOOKUP(C24:EE24,'Characters Database'!$E$6:$K45, 7, False), )} -> Dark Defender | D25: Green Runner | E25: Dark Defender-Attacker | F25: Light Runner | G25: Blue Defender | H25: Red Defender | I25: Dark Attacker | J25: Dark Defender | K25: Light Attacker | L25: Blue Runner | M25: Green Defender | N25: Blue Defender | O25: Blue Attacker | P25: Green Runner | Q25: Red Defender | R25: Blue Attacker | S25: Red Runner | T25: Red Attacker | U25: Red Defender | V25: Green Attacker | W25: Green Defender | X25: Blue Attacker | Y25: Blue Defender | Z25: Red Attacker | AA25: Blue Runner | AB25: Green Runner | AC25: Blue Attacker | AD25: Red Defender | AE25: Blue Runner | AF25: Green Attacker | AG25: Blue Attacker | AH25: Green Runner | AI25: Red Defender | AJ25: Red Attacker | AK25: Red Defender | AL25: Green Attacker | AM25: Red Runner | AN25: Green Defender | AO25: Green Defender | AP25: Blue Runner | AQ25: Blue Defender | AR25: Green Runner | AS25: Blue Runner | AT25: Green Defender | AU25: Red Runner | AV25: Green Attacker | AW25: Red Attacker | AX25: Green Runner | AY25: Green Defender | AZ25: Blue Runner | BA25: Red Defender | BB25: Blue Attacker | BC25: Blue Defender | BD25: Green Attacker | BE25: Red Attacker | BF25: Blue Defender | BG25: Red Defender | BH25: Blue Attacker | BI25: Blue Defender | BJ25: Red Runner | BK25: Blue Attacker | BL25: Green Runner | BM25: Green Runner | BN25: Red Defender | BO25: Red Runner | BP25: Blue Attacker | BQ25: Green Defender | BR25: Red Runner | BS25: Green Attacker | BT25: Green Attacker | BU25: Red Defender | BV25: Red Runner | BW25: Green Runner | BX25: Blue Runner | BY25: Blue Attacker | BZ25: Blue Runner | CA25: Red Attacker | CB25: Green Runner | CC25: Blue Defender | CD25: Blue Attacker | CE25: Red Defender | CF25: Red Defender | CG25: Green Runner | CH25: Red Attacker | CI25: Blue Runner | CJ25: Blue Runner | CK25: Green Attacker | CL25: Red Runner | CM25: Green Defender | CN25: Blue Attacker | CO25: Blue Attacker | CP25: Red Runner | CQ25: Blue Runner | CR25: Green Attacker | CS25: Green Attacker | CT25: Blue Defender | CU25: Green Runner | CV25: Red Defender | CW25: Green Defender | CX25: Green Defender | CY25: Red Attacker | CZ25: Blue Attacker | DA25: Red Attacker | DB25: Blue Defender | DC25: Green Runner
A26: Limited Step Up | B26: =COUNTIF(28:28,"*") -> 4 | C26: {=IF(C28:EE28 <> "", IF(VLOOKUP(C28:EE28,'Characters Database'!$E$6:$I45, 5, False) = "", "-", IMAGE(VLOOKUP(C28:EE28,'Characters Database'!$E$6:$I45, 5, False))), )}
C27: {=IF(C28:EE28 <> "", IMAGE(VLOOKUP(C28:EE28,'Characters Database'!$E$6:$K45, 6, False)), )}
C28: =IFERROR(__xludf.DUMMYFUNCTION("TRANSPOSE(QUERY('Characters Database'!A$6:K45, ""Select E Where F = '"" & A26 & ""'""))"),"FILM RED Tony Tony Chopper") -> FILM RED Tony Tony Chopper | D28: =IFERROR(__xludf.DUMMYFUNCTION("""COMPUTED_VALUE"""),"FILM RED Nami") -> FILM RED Nami | E28: =IFERROR(__xludf.DUMMYFUNCTION("""COMPUTED_VALUE"""),"STAMPEDE Sabo") -> STAMPEDE Sabo | F28: =IFERROR(__xludf.DUMMYFUNCTION("""COMPUTED_VALUE"""),"STAMPEDE Smoker") -> STAMPEDE Smoker
C29: {=IF(C28:EE28 <> "", VLOOKUP(C28:EE28,'Characters Database'!$E$6:$K45, 7, False), )} -> Green Defender | D29: Blue Runner | E29: Green Attacker | F29: Blue Defender
A30: Bounty Festival | B30: =COUNTIF(32:32,"*") -> 132 | C30: {=IF(C32:EE32 <> "", IF(VLOOKUP(C32:EE32,'Characters Database'!$E$6:$I45, 5, False) = "", "-", IMAGE(VLOOKUP(C32:EE32,'Characters Database'!$E$6:$I45, 5, False))), )}
C31: {=IF(C32:EE32 <> "", IMAGE(VLOOKUP(C32:EE32,'Characters Database'!$E$6:$K45, 6, False)), )}
